2024-08-30 02:02:21,563 ERROR: Exception on /index [GET] [in /home/tingchieh/Documents/flask-study/.venv/lib/python3.12/site-packages/flask/app.py:825]
Traceback (most recent call last):
  File "/home/tingchieh/Documents/flask-study/.venv/lib/python3.12/site-packages/flask/app.py", line 1455, in wsgi_app
    response = self.full_dispatch_request()
               ^^^^^^^^^^^^^^^^^^^^^^^^^^^^
  File "/home/tingchieh/Documents/flask-study/.venv/lib/python3.12/site-packages/flask/app.py", line 869, in full_dispatch_request
    rv = self.handle_user_exception(e)
         ^^^^^^^^^^^^^^^^^^^^^^^^^^^^^
  File "/home/tingchieh/Documents/flask-study/.venv/lib/python3.12/site-packages/flask/app.py", line 867, in full_dispatch_request
    rv = self.dispatch_request()
         ^^^^^^^^^^^^^^^^^^^^^^^
  File "/home/tingchieh/Documents/flask-study/.venv/lib/python3.12/site-packages/flask/app.py", line 852, in dispatch_request
    return self.ensure_sync(self.view_functions[rule.endpoint])(**view_args)
           ^^^^^^^^^^^^^^^^^^^^^^^^^^^^^^^^^^^^^^^^^^^^^^^^^^^^^^^^^^^^^^^^^
  File "/home/tingchieh/Documents/flask-study/app/routes.py", line 40, in index
    posts = db.paginate(current_user.following_posts(), page=page,
                        ^^^^^^^^^^^^^^^^^^^^^^^^^^^^
AttributeError: 'AnonymousUserMixin' object has no attribute 'following_posts'
2024-08-30 02:02:29,254 ERROR: Exception on /index [GET] [in /home/tingchieh/Documents/flask-study/.venv/lib/python3.12/site-packages/flask/app.py:825]
Traceback (most recent call last):
  File "/home/tingchieh/Documents/flask-study/.venv/lib/python3.12/site-packages/flask/app.py", line 1455, in wsgi_app
    response = self.full_dispatch_request()
               ^^^^^^^^^^^^^^^^^^^^^^^^^^^^
  File "/home/tingchieh/Documents/flask-study/.venv/lib/python3.12/site-packages/flask/app.py", line 869, in full_dispatch_request
    rv = self.handle_user_exception(e)
         ^^^^^^^^^^^^^^^^^^^^^^^^^^^^^
  File "/home/tingchieh/Documents/flask-study/.venv/lib/python3.12/site-packages/flask/app.py", line 867, in full_dispatch_request
    rv = self.dispatch_request()
         ^^^^^^^^^^^^^^^^^^^^^^^
  File "/home/tingchieh/Documents/flask-study/.venv/lib/python3.12/site-packages/flask/app.py", line 852, in dispatch_request
    return self.ensure_sync(self.view_functions[rule.endpoint])(**view_args)
           ^^^^^^^^^^^^^^^^^^^^^^^^^^^^^^^^^^^^^^^^^^^^^^^^^^^^^^^^^^^^^^^^^
  File "/home/tingchieh/Documents/flask-study/app/routes.py", line 40, in index
    posts = db.paginate(current_user.following_posts(), page=page,
                        ^^^^^^^^^^^^^^^^^^^^^^^^^^^^
AttributeError: 'AnonymousUserMixin' object has no attribute 'following_posts'
2024-08-30 02:02:39,887 ERROR: Exception on /index [GET] [in /home/tingchieh/Documents/flask-study/.venv/lib/python3.12/site-packages/flask/app.py:825]
Traceback (most recent call last):
  File "/home/tingchieh/Documents/flask-study/.venv/lib/python3.12/site-packages/flask/app.py", line 1455, in wsgi_app
    response = self.full_dispatch_request()
               ^^^^^^^^^^^^^^^^^^^^^^^^^^^^
  File "/home/tingchieh/Documents/flask-study/.venv/lib/python3.12/site-packages/flask/app.py", line 869, in full_dispatch_request
    rv = self.handle_user_exception(e)
         ^^^^^^^^^^^^^^^^^^^^^^^^^^^^^
  File "/home/tingchieh/Documents/flask-study/.venv/lib/python3.12/site-packages/flask/app.py", line 867, in full_dispatch_request
    rv = self.dispatch_request()
         ^^^^^^^^^^^^^^^^^^^^^^^
  File "/home/tingchieh/Documents/flask-study/.venv/lib/python3.12/site-packages/flask/app.py", line 852, in dispatch_request
    return self.ensure_sync(self.view_functions[rule.endpoint])(**view_args)
           ^^^^^^^^^^^^^^^^^^^^^^^^^^^^^^^^^^^^^^^^^^^^^^^^^^^^^^^^^^^^^^^^^
  File "/home/tingchieh/Documents/flask-study/app/routes.py", line 40, in index
    posts = db.paginate(current_user.following_posts(), page=page,
                        ^^^^^^^^^^^^^^^^^^^^^^^^^^^^
AttributeError: 'AnonymousUserMixin' object has no attribute 'following_posts'
2024-08-30 02:02:43,006 ERROR: Exception on /index [GET] [in /home/tingchieh/Documents/flask-study/.venv/lib/python3.12/site-packages/flask/app.py:825]
Traceback (most recent call last):
  File "/home/tingchieh/Documents/flask-study/.venv/lib/python3.12/site-packages/flask/app.py", line 1455, in wsgi_app
    response = self.full_dispatch_request()
               ^^^^^^^^^^^^^^^^^^^^^^^^^^^^
  File "/home/tingchieh/Documents/flask-study/.venv/lib/python3.12/site-packages/flask/app.py", line 869, in full_dispatch_request
    rv = self.handle_user_exception(e)
         ^^^^^^^^^^^^^^^^^^^^^^^^^^^^^
  File "/home/tingchieh/Documents/flask-study/.venv/lib/python3.12/site-packages/flask/app.py", line 867, in full_dispatch_request
    rv = self.dispatch_request()
         ^^^^^^^^^^^^^^^^^^^^^^^
  File "/home/tingchieh/Documents/flask-study/.venv/lib/python3.12/site-packages/flask/app.py", line 852, in dispatch_request
    return self.ensure_sync(self.view_functions[rule.endpoint])(**view_args)
           ^^^^^^^^^^^^^^^^^^^^^^^^^^^^^^^^^^^^^^^^^^^^^^^^^^^^^^^^^^^^^^^^^
  File "/home/tingchieh/Documents/flask-study/app/routes.py", line 40, in index
    posts = db.paginate(current_user.following_posts(), page=page,
                        ^^^^^^^^^^^^^^^^^^^^^^^^^^^^
AttributeError: 'AnonymousUserMixin' object has no attribute 'following_posts'
2024-08-30 02:02:45,541 ERROR: Exception on /index [GET] [in /home/tingchieh/Documents/flask-study/.venv/lib/python3.12/site-packages/flask/app.py:825]
Traceback (most recent call last):
  File "/home/tingchieh/Documents/flask-study/.venv/lib/python3.12/site-packages/flask/app.py", line 1455, in wsgi_app
    response = self.full_dispatch_request()
               ^^^^^^^^^^^^^^^^^^^^^^^^^^^^
  File "/home/tingchieh/Documents/flask-study/.venv/lib/python3.12/site-packages/flask/app.py", line 869, in full_dispatch_request
    rv = self.handle_user_exception(e)
         ^^^^^^^^^^^^^^^^^^^^^^^^^^^^^
  File "/home/tingchieh/Documents/flask-study/.venv/lib/python3.12/site-packages/flask/app.py", line 867, in full_dispatch_request
    rv = self.dispatch_request()
         ^^^^^^^^^^^^^^^^^^^^^^^
  File "/home/tingchieh/Documents/flask-study/.venv/lib/python3.12/site-packages/flask/app.py", line 852, in dispatch_request
    return self.ensure_sync(self.view_functions[rule.endpoint])(**view_args)
           ^^^^^^^^^^^^^^^^^^^^^^^^^^^^^^^^^^^^^^^^^^^^^^^^^^^^^^^^^^^^^^^^^
  File "/home/tingchieh/Documents/flask-study/app/routes.py", line 40, in index
    posts = db.paginate(current_user.following_posts(), page=page,
                        ^^^^^^^^^^^^^^^^^^^^^^^^^^^^
AttributeError: 'AnonymousUserMixin' object has no attribute 'following_posts'
2024-08-30 02:03:26,501 INFO: Microblog startup [in /home/tingchieh/Documents/flask-study/app/__init__.py:57]
2024-08-30 02:03:30,960 ERROR: Exception on /index [GET] [in /home/tingchieh/Documents/flask-study/.venv/lib/python3.12/site-packages/flask/app.py:825]
Traceback (most recent call last):
  File "/home/tingchieh/Documents/flask-study/.venv/lib/python3.12/site-packages/flask/app.py", line 1455, in wsgi_app
    response = self.full_dispatch_request()
               ^^^^^^^^^^^^^^^^^^^^^^^^^^^^
  File "/home/tingchieh/Documents/flask-study/.venv/lib/python3.12/site-packages/flask/app.py", line 869, in full_dispatch_request
    rv = self.handle_user_exception(e)
         ^^^^^^^^^^^^^^^^^^^^^^^^^^^^^
  File "/home/tingchieh/Documents/flask-study/.venv/lib/python3.12/site-packages/flask/app.py", line 867, in full_dispatch_request
    rv = self.dispatch_request()
         ^^^^^^^^^^^^^^^^^^^^^^^
  File "/home/tingchieh/Documents/flask-study/.venv/lib/python3.12/site-packages/flask/app.py", line 852, in dispatch_request
    return self.ensure_sync(self.view_functions[rule.endpoint])(**view_args)
           ^^^^^^^^^^^^^^^^^^^^^^^^^^^^^^^^^^^^^^^^^^^^^^^^^^^^^^^^^^^^^^^^^
  File "/home/tingchieh/Documents/flask-study/app/routes.py", line 40, in index
    posts = db.paginate(current_user.following_posts(), page=page,
                        ^^^^^^^^^^^^^^^^^^^^^^^^^^^^
AttributeError: 'AnonymousUserMixin' object has no attribute 'following_posts'
2024-08-30 02:03:39,700 ERROR: Exception on /index [GET] [in /home/tingchieh/Documents/flask-study/.venv/lib/python3.12/site-packages/flask/app.py:825]
Traceback (most recent call last):
  File "/home/tingchieh/Documents/flask-study/.venv/lib/python3.12/site-packages/flask/app.py", line 1455, in wsgi_app
    response = self.full_dispatch_request()
               ^^^^^^^^^^^^^^^^^^^^^^^^^^^^
  File "/home/tingchieh/Documents/flask-study/.venv/lib/python3.12/site-packages/flask/app.py", line 869, in full_dispatch_request
    rv = self.handle_user_exception(e)
         ^^^^^^^^^^^^^^^^^^^^^^^^^^^^^
  File "/home/tingchieh/Documents/flask-study/.venv/lib/python3.12/site-packages/flask/app.py", line 867, in full_dispatch_request
    rv = self.dispatch_request()
         ^^^^^^^^^^^^^^^^^^^^^^^
  File "/home/tingchieh/Documents/flask-study/.venv/lib/python3.12/site-packages/flask/app.py", line 852, in dispatch_request
    return self.ensure_sync(self.view_functions[rule.endpoint])(**view_args)
           ^^^^^^^^^^^^^^^^^^^^^^^^^^^^^^^^^^^^^^^^^^^^^^^^^^^^^^^^^^^^^^^^^
  File "/home/tingchieh/Documents/flask-study/app/routes.py", line 40, in index
    posts = db.paginate(current_user.following_posts(), page=page,
                        ^^^^^^^^^^^^^^^^^^^^^^^^^^^^
AttributeError: 'AnonymousUserMixin' object has no attribute 'following_posts'
